2021-07-29 04:10:22,642 ERROR: Exception on /edit_profile [GET] [in c:\users\penie\hcpd-system\venv\lib\site-packages\flask\app.py:1454
Traceback (most recent call last):
  File "c:\users\penie\hcpd-system\venv\lib\site-packages\flask\app.py", line 2070, in wsgi_app
    response = self.full_dispatch_request()
  File "c:\users\penie\hcpd-system\venv\lib\site-packages\flask\app.py", line 1515, in full_dispatch_request
    rv = self.handle_user_exception(e)
  File "c:\users\penie\hcpd-system\venv\lib\site-packages\flask\app.py", line 1513, in full_dispatch_request
    rv = self.dispatch_request()
  File "c:\users\penie\hcpd-system\venv\lib\site-packages\flask\app.py", line 1499, in dispatch_request
    return self.ensure_sync(self.view_functions[rule.endpoint])(**req.view_args)
  File "c:\users\penie\hcpd-system\venv\lib\site-packages\flask_login\utils.py", line 272, in decorated_view
    return func(*args, **kwargs)
  File "C:\Users\penie\hcpd-system\app\routes.py", line 79, in edit_profile
    form = EditProfile()
  File "c:\users\penie\hcpd-system\venv\lib\site-packages\wtforms\form.py", line 208, in __call__
    return type.__call__(cls, *args, **kwargs)
TypeError: __init__() missing 1 required positional argument: 'original_username'
2021-07-29 04:10:28,084 ERROR: Exception on /edit_profile [GET] [in c:\users\penie\hcpd-system\venv\lib\site-packages\flask\app.py:1454
Traceback (most recent call last):
  File "c:\users\penie\hcpd-system\venv\lib\site-packages\flask\app.py", line 2070, in wsgi_app
    response = self.full_dispatch_request()
  File "c:\users\penie\hcpd-system\venv\lib\site-packages\flask\app.py", line 1515, in full_dispatch_request
    rv = self.handle_user_exception(e)
  File "c:\users\penie\hcpd-system\venv\lib\site-packages\flask\app.py", line 1513, in full_dispatch_request
    rv = self.dispatch_request()
  File "c:\users\penie\hcpd-system\venv\lib\site-packages\flask\app.py", line 1499, in dispatch_request
    return self.ensure_sync(self.view_functions[rule.endpoint])(**req.view_args)
  File "c:\users\penie\hcpd-system\venv\lib\site-packages\flask_login\utils.py", line 272, in decorated_view
    return func(*args, **kwargs)
  File "C:\Users\penie\hcpd-system\app\routes.py", line 79, in edit_profile
    form = EditProfile()
  File "c:\users\penie\hcpd-system\venv\lib\site-packages\wtforms\form.py", line 208, in __call__
    return type.__call__(cls, *args, **kwargs)
TypeError: __init__() missing 1 required positional argument: 'original_username'
2021-07-29 05:07:10,086 ERROR: Exception on / [GET] [in c:\users\penie\hcpd-system\venv\lib\site-packages\flask\app.py:1454
Traceback (most recent call last):
  File "c:\users\penie\hcpd-system\venv\lib\site-packages\flask\app.py", line 2070, in wsgi_app
    response = self.full_dispatch_request()
  File "c:\users\penie\hcpd-system\venv\lib\site-packages\flask\app.py", line 1515, in full_dispatch_request
    rv = self.handle_user_exception(e)
  File "c:\users\penie\hcpd-system\venv\lib\site-packages\flask\app.py", line 1513, in full_dispatch_request
    rv = self.dispatch_request()
  File "c:\users\penie\hcpd-system\venv\lib\site-packages\flask\app.py", line 1499, in dispatch_request
    return self.ensure_sync(self.view_functions[rule.endpoint])(**req.view_args)
  File "c:\users\penie\hcpd-system\venv\lib\site-packages\flask_login\utils.py", line 272, in decorated_view
    return func(*args, **kwargs)
  File "C:\Users\penie\hcpd-system\app\routes.py", line 21, in home_page
    return render_template('home.html', users=users)
  File "c:\users\penie\hcpd-system\venv\lib\site-packages\flask\templating.py", line 147, in render_template
    return _render(
  File "c:\users\penie\hcpd-system\venv\lib\site-packages\flask\templating.py", line 128, in _render
    rv = template.render(context)
  File "c:\users\penie\hcpd-system\venv\lib\site-packages\jinja2\environment.py", line 1304, in render
    self.environment.handle_exception()
  File "c:\users\penie\hcpd-system\venv\lib\site-packages\jinja2\environment.py", line 925, in handle_exception
    raise rewrite_traceback_stack(source=source)
  File "C:\Users\penie\hcpd-system\app\templates\home.html", line 1, in top-level template code
    {% extends "base.html" %}
  File "c:\users\penie\hcpd-system\venv\lib\site-packages\jinja2\environment.py", line 925, in handle_exception
    raise rewrite_traceback_stack(source=source)
  File "C:\Users\penie\hcpd-system\app\templates\base.html", line 67, in template
    {% block content %}{% endblock %}
jinja2.exceptions.TemplateAssertionError: block 'content' defined twice
2021-07-29 13:28:34,064 ERROR: Exception on /rater [GET] [in c:\users\penie\hcpd-system\venv\lib\site-packages\flask\app.py:1454
Traceback (most recent call last):
  File "c:\users\penie\hcpd-system\venv\lib\site-packages\flask\app.py", line 2070, in wsgi_app
    response = self.full_dispatch_request()
  File "c:\users\penie\hcpd-system\venv\lib\site-packages\flask\app.py", line 1515, in full_dispatch_request
    rv = self.handle_user_exception(e)
  File "c:\users\penie\hcpd-system\venv\lib\site-packages\flask\app.py", line 1513, in full_dispatch_request
    rv = self.dispatch_request()
  File "c:\users\penie\hcpd-system\venv\lib\site-packages\flask\app.py", line 1499, in dispatch_request
    return self.ensure_sync(self.view_functions[rule.endpoint])(**req.view_args)
  File "c:\users\penie\hcpd-system\venv\lib\site-packages\flask_login\utils.py", line 272, in decorated_view
    return func(*args, **kwargs)
  File "C:\Users\penie\hcpd-system\app\routes.py", line 106, in rater
    form.rating.data = current_user.rating
AttributeError: 'Usernames' object has no attribute 'rating'
2021-07-29 13:28:36,341 ERROR: Exception on /rater [GET] [in c:\users\penie\hcpd-system\venv\lib\site-packages\flask\app.py:1454
Traceback (most recent call last):
  File "c:\users\penie\hcpd-system\venv\lib\site-packages\flask\app.py", line 2070, in wsgi_app
    response = self.full_dispatch_request()
  File "c:\users\penie\hcpd-system\venv\lib\site-packages\flask\app.py", line 1515, in full_dispatch_request
    rv = self.handle_user_exception(e)
  File "c:\users\penie\hcpd-system\venv\lib\site-packages\flask\app.py", line 1513, in full_dispatch_request
    rv = self.dispatch_request()
  File "c:\users\penie\hcpd-system\venv\lib\site-packages\flask\app.py", line 1499, in dispatch_request
    return self.ensure_sync(self.view_functions[rule.endpoint])(**req.view_args)
  File "c:\users\penie\hcpd-system\venv\lib\site-packages\flask_login\utils.py", line 272, in decorated_view
    return func(*args, **kwargs)
  File "C:\Users\penie\hcpd-system\app\routes.py", line 106, in rater
    form.rating.data = current_user.rating
AttributeError: 'Usernames' object has no attribute 'rating'
2021-07-29 13:29:52,888 ERROR: Exception on /rater [GET] [in c:\users\penie\hcpd-system\venv\lib\site-packages\flask\app.py:1454
Traceback (most recent call last):
  File "c:\users\penie\hcpd-system\venv\lib\site-packages\flask\app.py", line 2070, in wsgi_app
    response = self.full_dispatch_request()
  File "c:\users\penie\hcpd-system\venv\lib\site-packages\flask\app.py", line 1515, in full_dispatch_request
    rv = self.handle_user_exception(e)
  File "c:\users\penie\hcpd-system\venv\lib\site-packages\flask\app.py", line 1513, in full_dispatch_request
    rv = self.dispatch_request()
  File "c:\users\penie\hcpd-system\venv\lib\site-packages\flask\app.py", line 1499, in dispatch_request
    return self.ensure_sync(self.view_functions[rule.endpoint])(**req.view_args)
  File "c:\users\penie\hcpd-system\venv\lib\site-packages\flask_login\utils.py", line 272, in decorated_view
    return func(*args, **kwargs)
  File "C:\Users\penie\hcpd-system\app\routes.py", line 108, in rater
    return render_template('rater.html', user_ratings=user_ratings, form=form)
UnboundLocalError: local variable 'user_ratings' referenced before assignment
